{"uuid": "c8541c79-10b1-4702-994c-8f33ee57d26c", "children": ["2b3e3a61-91c7-44b7-8e2a-489d515fc399"], "befores": [{"name": "dynamic_test_user", "status": "failed", "statusDetails": {"message": "Failed: Fixture \"test_user\" called directly. Fixtures are not meant to be called directly,\nbut are created automatically when test functions request them as parameters.\nSee https://docs.pytest.org/en/stable/explanation/fixtures.html for more information about fixtures, and\nhttps://docs.pytest.org/en/stable/deprecations.html#calling-fixtures-directly about how to update your code.\n", "trace": "  File \"D:\\Anaconda3\\Lib\\site-packages\\pluggy\\_callers.py\", line 39, in _multicall\n    res = hook_impl.function(*args)\n          ^^^^^^^^^^^^^^^^^^^^^^^^^\n  File \"D:\\Anaconda3\\Lib\\site-packages\\_pytest\\fixtures.py\", line 1123, in pytest_fixture_setup\n    result = call_fixture_func(fixturefunc, request, kwargs)\n             ^^^^^^^^^^^^^^^^^^^^^^^^^^^^^^^^^^^^^^^^^^^^^^^\n  File \"D:\\Anaconda3\\Lib\\site-packages\\_pytest\\fixtures.py\", line 895, in call_fixture_func\n    fixture_result = next(generator)\n                     ^^^^^^^^^^^^^^^\n  File \"D:\\工作记录\\项目说明\\api_test\\tests\\test_user_auth.py\", line 89, in dynamic_test_user\n    test_user_data = create_test_user()\n                     ^^^^^^^^^^^^^^^^^^\n  File \"D:\\Anaconda3\\Lib\\site-packages\\_pytest\\fixtures.py\", line 1168, in result\n    fail(message, pytrace=False)\n  File \"D:\\Anaconda3\\Lib\\site-packages\\_pytest\\outcomes.py\", line 198, in fail\n    raise Failed(msg=reason, pytrace=pytrace)\n"}, "start": 1754636926970, "stop": 1754636926970}], "start": 1754636926970, "stop": 1754636926981}